Workbook
Name Slicer_Age_Group: #N/A
Name Slicer_Category: #N/A
Name Slicer_Discount_Group: #N/A
Name Slicer_Year: #N/A

Sheet products 
A1: Product ID | B1: Category | C1: Sub-category | D1: Product Name | E1: Brand Name | F1: Size | G1: Color | H1: Ratings
A2: P0001 | B2: Women | C2: Topwear | D2: T-Shirts | E2: Roadster | F2: 40 | G2: Black | H2: 4
A3: P0002 | B3: Women | C3: Topwear | D3: T-Shirts | E3: Roadster | F3: 40 | G3: Blue | H3: 5
A4: P0003 | B4: Women | C4: Topwear | D4: T-Shirts | E4: Roadster | F4: 42 | G4: White | H4: 3
A5: P0004 | B5: Women | C5: Topwear | D5: T-Shirts | E5: Roadster | F5: 44 | G5: Green | H5: 2
A6: P0005 | B6: Women | C6: Topwear | D6: T-Shirts | E6: Puma | F6: 38 | G6: Olive | H6: 5
A7: P0006 | B7: Women | C7: Topwear | D7: T-Shirts | E7: Puma | F7: 46 | G7: Pink | H7: 4
A8: P0007 | B8: Women | C8: Topwear | D8: T-Shirts | E8: Puma | F8: 38 | G8: Orange | H8: 3
A9: P0008 | B9: Women | C9: Topwear | D9: T-Shirts | E9: Puma | F9: 38 | G9: Beige | H9: 5
A10: P0009 | B10: Women | C10: Topwear | D10: T-Shirts | E10: Puma | F10: 38 | G10: Off white | H10: 4
A11: P0010 | B11: Women | C11: Topwear | D11: T-Shirts | E11: Puma | F11: 38 | G11: Purple | H11: 2
A12: P0011 | B12: Women | C12: Topwear | D12: T-Shirts | E12: Puma | F12: 38 | G12: Peach | H12: 5
A13: P0012 | B13: Women | C13: Topwear | D13: T-Shirts | E13: Puma | F13: 42 | G13: Sea Green | H13: 5
... A841: P0840 | B841: Men | C841: Bottomwear | D841: Pants | E841: Jockey | F841: 36 | G841: Orange | H841: 3
A842: P0841 | B842: Men | C842: Footwear | D842: Casual Shoes | E842: Puma | F842: 6 UK | G842: Green | H842: 5
A843: P0842 | B843: Men | C843: Footwear | D843: Casual Shoes | E843: Puma | F843: 7 UK | G843: Purple | H843: 5
A844: P0843 | B844: Men | C844: Footwear | D844: Casual Shoes | E844: Puma | F844: 8 UK | G844: White | H844: 4
A845: P0844 | B845: Men | C845: Footwear | D845: Casual Shoes | E845: Puma | F845: 9 UK | G845: Off white | H845: 3
A846: P0845 | B846: Men | C846: Footwear | D846: Casual Shoes | E846: Puma | F846: 10 UK | G846: Off white | H846: 3
A847: P0846 | B847: Men | C847: Footwear | D847: Casual Shoes | E847: Puma | F847: 11 UK | G847: Off white | H847: 5
A848: P0847 | B848: Men | C848: Footwear | D848: Casual Shoes | E848: Puma | F848: 11 UK | G848: Off white | H848: 5
A849: P0848 | B849: Men | C849: Footwear | D849: Casual Shoes | E849: Puma | F849: 11 UK | G849: Off white | H849: 4
A850: P0849 | B850: Men | C850: Footwear | D850: Casual Shoes | E850: Puma | F850: 11 UK | G850: Off white | H850: 2
A851: P0850 | B851: Men | C851: Footwear | D851: Casual Shoes | E851: Puma | F851: 11 UK | G851: Off white | H851: 3
A852: P0851 | B852: Men | C852: Footwear | D852: Casual Shoes | E852: Puma | F852: 11 UK | G852: Off white | H852: 4
A853: P0852 | B853: Men | C853: Footwear | D853: Casual Shoes | E853: Puma | F853: 11 UK | G853: Off white | H853: 5
... A1463: P1462 | B1463: Women | C1463: Western Wear | D1463: T-Shirts | E1463: ONLY | F1463: M | G1463: Pink | H1463: 4
A1464: P1463 | B1464: Women | C1464: Western Wear | D1464: Jeans | E1464: Roadster | F1464: 30 | G1464: Pink | H1464: 2
A1465: P1464 | B1465: Women | C1465: Western Wear | D1465: Jeans | E1465: Roadster | F1465: 30 | G1465: Pink | H1465: 5
A1466: P1465 | B1466: Women | C1466: Western Wear | D1466: Jeans | E1466: Roadster | F1466: 30 | G1466: Pink | H1466: 5
A1467: P1466 | B1467: Women | C1467: Western Wear | D1467: Jeans | E1467: Roadster | F1467: 30 | G1467: Pink | H1467: 4
A1468: P1467 | B1468: Women | C1468: Western Wear | D1468: Jeans | E1468: Roadster | F1468: 30 | G1468: Pink | H1468: 4
A1469: P1468 | B1469: Women | C1469: Western Wear | D1469: Jeans | E1469: Roadster | F1469: 30 | G1469: Pink | H1469: 4
A1470: P1469 | B1470: Women | C1470: Western Wear | D1470: Jeans | E1470: Roadster | F1470: 30 | G1470: Blue | H1470: 3
A1471: P1470 | B1471: Women | C1471: Western Wear | D1471: Jeans | E1471: Roadster | F1471: 30 | G1471: Blue | H1471: 5
A1472: P1471 | B1472: Women | C1472: Western Wear | D1472: Jeans | E1472: Roadster | F1472: 32 | G1472: Blue | H1472: 4
A1473: P1472 | B1473: Women | C1473: Western Wear | D1473: Jeans | E1473: Roadster | F1473: 32 | G1473: Navy Blue | H1473: 2
A1474: P1473 | B1474: Women | C1474: Western Wear | D1474: Jeans | E1474: Roadster | F1474: 32 | G1474: Navy Blue | H1474: 5
A1475: P1474 | B1475: Women | C1475: Western Wear | D1475: Jeans | E1475: Roadster | F1475: 32 | G1475: Navy Blue | H1475: 5
... A1588: P1587 | B1588: Women | C1588: Western Wear | D1588: Jeans | E1588: Allen Solly | F1588: 30 | G1588: Khaki | H1588: 4
...

Sheet customers
A1: Customer ID | B1: Customer Age | C1: City | D1: State
A2: C001 | B2: 30 | C2: Mumbai | D2: Maharashtra
A3: C002 | B3: 35 | C3: Mumbai | D3: Maharashtra
A4: C003 | B4: 36 | C4: Mumbai | D4: Maharashtra
A5: C004 | B5: 40 | C5: Pune | D5: Maharashtra
A6: C005 | B6: 25 | C6: Pune | D6: Maharashtra
A7: C006 | B7: 16 | C7: Pune | D7: Maharashtra
A8: C007 | B8: 23 | C8: Pune | D8: Maharashtra
A9: C008 | B9: 22 | C9: Pune | D9: Maharashtra
A10: C009 | B10: 17 | C10: Hyderabad | D10: Telangana
A11: C010 | B11: 19 | C11: Hyderabad | D11: Telangana
A12: C011 | B12: 18 | C12: Hyderabad | D12: Telangana
A13: C012 | B13: 20 | C13: Hyderabad | D13: Telangana
... A101: C100 | B101: 40 | C101: Udaipur | D101: Rajasthan

Sheet fact_orders
A1: Order ID | B1: Customer ID | C1: Product ID | D1: Date | E1: Original Price | F1: Discount%
A2: OD0001 | B2: C001 | C2: P0001 | D2: =RANDBETWEEN(DATE(2021,1,1),DATE(2023,3,31)) -> 44645 | E2: 349 | F2: 0.3
A3: OD0002 | B3: C002 | C3: P0001 | D3: =RANDBETWEEN(DATE(2021,1,1),DATE(2023,3,31)) -> 44372 | E3: 350 | F3: 0.3
A4: OD0003 | B4: C003 | C4: P0001 | D4: =RANDBETWEEN(DATE(2021,1,1),DATE(2023,3,31)) -> 44936 | E4: 351 | F4: 0.3
A5: OD0004 | B5: C004 | C5: P0001 | D5: =RANDBETWEEN(DATE(2021,1,1),DATE(2023,3,31)) -> 44976 | E5: 352 | F5: 0.25
A6: OD0005 | B6: C005 | C6: P0001 | D6: =RANDBETWEEN(DATE(2021,1,1),DATE(2023,3,31)) -> 44460 | E6: 353 | F6: 0.25
A7: OD0006 | B7: C006 | C7: P0002 | D7: =RANDBETWEEN(DATE(2021,1,1),DATE(2023,3,31)) -> 44601 | E7: 354 | F7: 0.3
A8: OD0007 | B8: C007 | C8: P0003 | D8: =RANDBETWEEN(DATE(2021,1,1),DATE(2023,3,31)) -> 44642 | E8: 355 | F8: 0.3
A9: OD0008 | B9: C008 | C9: P0004 | D9: =RANDBETWEEN(DATE(2021,1,1),DATE(2023,3,31)) -> 44640 | E9: 356 | F9: 0.3
A10: OD0009 | B10: C009 | C10: P0005 | D10: =RANDBETWEEN(DATE(2021,1,1),DATE(2023,3,31)) -> 44366 | E10: 2222 | F10: 0.4
A11: OD0010 | B11: C010 | C11: P0006 | D11: =RANDBETWEEN(DATE(2021,1,1),DATE(2023,3,31)) -> 44807 | E11: 2342 | F11: 0.4
A12: OD0011 | B12: C011 | C12: P0007 | D12: =RANDBETWEEN(DATE(2021,1,1),DATE(2023,3,31)) -> 44713 | E12: 2241 | F12: 0.4
A13: OD0012 | B13: C012 | C13: P0007 | D13: =RANDBETWEEN(DATE(2021,1,1),DATE(2023,3,31)) -> 44243 | E13: 2253 | F13: 0.4
... A3072: OD3071 | B3072: C056 | C3072: P2711 | D3072: =RANDBETWEEN(DATE(2021,1,1),DATE(2023,3,31)) -> 44388 | E3072: 555 | F3072: 0.25
A3073: OD3072 | B3073: C057 | C3073: P2712 | D3073: =RANDBETWEEN(DATE(2021,1,1),DATE(2023,3,31)) -> 44676 | E3073: =RANDBETWEEN(600, 2000) -> 986 | F3073: 0.3
A3074: OD3073 | B3074: C058 | C3074: P2713 | D3074: =RANDBETWEEN(DATE(2021,1,1),DATE(2023,3,31)) -> 44650 | E3074: =RANDBETWEEN(600, 2000) -> 1778 | F3074: 0.3
A3075: OD3074 | B3075: C059 | C3075: P2714 | D3075: =RANDBETWEEN(DATE(2021,1,1),DATE(2023,3,31)) -> 44786 | E3075: =RANDBETWEEN(600, 2000) -> 1175 | F3075: 0.3
A3076: OD3075 | B3076: C060 | C3076: P2715 | D3076: =RANDBETWEEN(DATE(2021,1,1),DATE(2023,3,31)) -> 44409 | E3076: =RANDBETWEEN(600, 2000) -> 1502 | F3076: 0.25
A3077: OD3076 | B3077: C061 | C3077: P2716 | D3077: =RANDBETWEEN(DATE(2021,1,1),DATE(2023,3,31)) -> 44980 | E3077: =RANDBETWEEN(600, 2000) -> 1187 | F3077: 0.25
A3078: OD3077 | B3078: C062 | C3078: P2717 | D3078: =RANDBETWEEN(DATE(2021,1,1),DATE(2023,3,31)) -> 44844 | E3078: =RANDBETWEEN(600, 2000) -> 1764 | F3078: 0.3
A3079: OD3078 | B3079: C063 | C3079: P2718 | D3079: =RANDBETWEEN(DATE(2021,1,1),DATE(2023,3,31)) -> 44826 | E3079: =RANDBETWEEN(600, 2000) -> 656 | F3079: 0.3
A3080: OD3079 | B3080: C064 | C3080: P2719 | D3080: =RANDBETWEEN(DATE(2021,1,1),DATE(2023,3,31)) -> 44950 | E3080: =RANDBETWEEN(600, 2000) -> 1367 | F3080: 0.3
A3081: OD3080 | B3081: C065 | C3081: P2720 | D3081: =RANDBETWEEN(DATE(2021,1,1),DATE(2023,3,31)) -> 44231 | E3081: =RANDBETWEEN(600, 2000) -> 712 | F3081: 0.4
A3082: OD3081 | B3082: C066 | C3082: P2721 | D3082: =RANDBETWEEN(DATE(2021,1,1),DATE(2023,3,31)) -> 44371 | E3082: =RANDBETWEEN(600, 2000) -> 1571 | F3082: 0.4
A3083: OD3082 | B3083: C067 | C3083: P2722 | D3083: =RANDBETWEEN(DATE(2021,1,1),DATE(2023,3,31)) -> 44563 | E3083: =RANDBETWEEN(600, 2000) -> 1828 | F3083: 0.4
A3084: OD3083 | B3084: C068 | C3084: P2723 | D3084: =RANDBETWEEN(DATE(2021,1,1),DATE(2023,3,31)) -> 44924 | E3084: =RANDBETWEEN(600, 2000) -> 743 | F3084: 0.4
... A3447: OD3446 | B3447: C031 | C3447: P3046 | D3447: =RANDBETWEEN(DATE(2021,1,1),DATE(2023,3,31)) -> 44477 | E3447: =RANDBETWEEN(600, 2000) -> 1934 | F3447: 0.39
A3448: OD3447 | B3448: C032 | C3448: P3047 | D3448: =RANDBETWEEN(DATE(2021,1,1),DATE(2023,3,31)) -> 44953 | E3448: 2245 | F3448: 0.39
A3449: OD3448 | B3449: C033 | C3449: P3048 | D3449: =RANDBETWEEN(DATE(2021,1,1),DATE(2023,3,31)) -> 44236 | E3449: 2354 | F3449: 0.39
A3450: OD3449 | B3450: C034 | C3450: P3049 | D3450: =RANDBETWEEN(DATE(2021,1,1),DATE(2023,3,31)) -> 44932 | E3450: 2214 | F3450: 0.39
A3451: OD3450 | B3451: C035 | C3451: P3050 | D3451: =RANDBETWEEN(DATE(2021,1,1),DATE(2023,3,31)) -> 44919 | E3451: 2365 | F3451: 0.3
A3452: OD3451 | B3452: C036 | C3452: P3051 | D3452: =RANDBETWEEN(DATE(2021,1,1),DATE(2023,3,31)) -> 44667 | E3452: 2541 | F3452: 0.3
A3453: OD3452 | B3453: C037 | C3453: P3052 | D3453: =RANDBETWEEN(DATE(2021,1,1),DATE(2023,3,31)) -> 44307 | E3453: 1235 | F3453: 0.3
A3454: OD3453 | B3454: C038 | C3454: P3053 | D3454: =RANDBETWEEN(DATE(2021,1,1),DATE(2023,3,31)) -> 44772 | E3454: 22365 | F3454: 0.25
A3455: OD3454 | B3455: C039 | C3455: P3054 | D3455: =RANDBETWEEN(DATE(2021,1,1),DATE(2023,3,31)) -> 44442 | E3455: 2245 | F3455: 0.25
A3456: OD3455 | B3456: C040 | C3456: P3054 | D3456: =RANDBETWEEN(DATE(2021,1,1),DATE(2023,3,31)) -> 44695 | E3456: 2245 | F3456: 0.3
A3457: OD3456 | B3457: C041 | C3457: P3054 | D3457: =RANDBETWEEN(DATE(2021,1,1),DATE(2023,3,31)) -> 44671 | E3457: 2542 | F3457: 0.3
A3458: OD3457 | B3458: C042 | C3458: P3054 | D3458: =RANDBETWEEN(DATE(2021,1,1),DATE(2023,3,31)) -> 44241 | E3458: 2263 | F3458: 0.3
A3459: OD3458 | B3459: C043 | C3459: P3054 | D3459: =RANDBETWEEN(DATE(2021,1,1),DATE(2023,3,31)) -> 44310 | E3459: 6523 | F3459: 0.4
... A3467: OD3466 | B3467: C051 | C3467: P3057 | D3467: =RANDBETWEEN(DATE(2021,1,1),DATE(2023,3,31)) -> 44359 | E3467: 4454 | F3467: 0.45
...

Sheet Myntra Dataset
A1: Order ID | B1: Customer ID | C1: Product ID | D1: Date | E1: Month | F1: Year | G1: Original Price | H1: Discount | I1: Discount Group | J1: Revenue | K1: Age | L1: Age Group | M1: City | N1: State | O1: Category | P1: Sub-category | Q1: Product Name | R1: Brand Name | S1: Size | T1: Color | U1: Ratings
A2: OD0001 | B2: C001 | C2: P0001 | D2: =RANDBETWEEN(DATE(2021,1,1),DATE(2023,3,31)) -> 44873 | E2: =TEXT(Table1[[#This Row],[Date]],"mmm") -> Nov | F2: =TEXT(Table1[[#This Row],[Date]],"yyyy") -> 2022 | G2: 349 | H2: 0.3 | I2: {=_xlfn.IFS(Table1[[#This Row],[Discount]]<=0.2,"Low",Table1[[#This Row],[Discount]]<=0.4,"Medium",Table1[[#This Row],[Discount]]>0.4,"High")} -> Medium | J2: =Table1[[#This Row],[Original Price]]*(1-Table1[[#This Row],[Discount]]) -> 244.3 | K2: =VLOOKUP(B2,customers!$A$2:$D$101,2,0) -> 30 | L2: {=_xlfn.IFS(Table1[[#This Row],[Age]]<=12,"Kids",Table1[[#This Row],[Age]]<=19,"Teenage",Table1[[#This Row],[Age]]<=29,"Young Adult",Table1[[#This Row],[Age]]<=45,"Adult",Table1[[#This Row],[Age]]>=46,"Senior")} -> Adult | M2: =VLOOKUP(B2,customers!A$2:D$101,3,0) -> Mumbai | N2: =VLOOKUP(B2,customers!$A$2:$D$101,4,0) -> Maharashtra | O2: =VLOOKUP(C2,'products '!$A$2:$H$3072,2,0) -> Women | P2: =VLOOKUP(C2,'products '!$A$2:$H$3072,3,0) -> Topwear | Q2: =VLOOKUP(C2,'products '!$A$2:$H$3072,4,0) -> T-Shirts | R2: =VLOOKUP(C2,'products '!$A$2:$H$3072,5,0) -> Roadster | S2: =VLOOKUP(C2,'products '!$A$2:$H$3072,6,0) -> 40 | T2: =VLOOKUP(C2,'products '!$A$2:$H$3072,7,0) -> Black | U2: =VLOOKUP(C2,'products '!$A$2:$H$3072,8,0) -> 4
A3: OD0002 | B3: C002 | C3: P0001 | D3: =RANDBETWEEN(DATE(2021,1,1),DATE(2023,3,31)) -> 44464 | E3: =TEXT(Table1[[#This Row],[Date]],"mmm") -> Sep | F3: =TEXT(Table1[[#This Row],[Date]],"yyyy") -> 2021 | G3: 350 | H3: 0.3 | I3: {=_xlfn.IFS(Table1[[#This Row],[Discount]]<=0.2,"Low",Table1[[#This Row],[Discount]]<=0.4,"Medium",Table1[[#This Row],[Discount]]>0.4,"High")} -> Medium | J3: =Table1[[#This Row],[Original Price]]*(1-Table1[[#This Row],[Discount]]) -> 245 | K3: =VLOOKUP(B3,customers!$A$2:$D$101,2,0) -> 35 | L3: {=_xlfn.IFS(Table1[[#This Row],[Age]]<=12,"Kids",Table1[[#This Row],[Age]]<=19,"Teenage",Table1[[#This Row],[Age]]<=29,"Young Adult",Table1[[#This Row],[Age]]<=45,"Adult",Table1[[#This Row],[Age]]>=46,"Senior")} -> Adult | M3: =VLOOKUP(B3,customers!A$2:D$101,3,0) -> Mumbai | N3: =VLOOKUP(B3,customers!$A$2:$D$101,4,0) -> Maharashtra | O3: =VLOOKUP(C3,'products '!$A$2:$H$3072,2,0) -> Women | P3: =VLOOKUP(C3,'products '!$A$2:$H$3072,3,0) -> Topwear | Q3: =VLOOKUP(C3,'products '!$A$2:$H$3072,4,0) -> T-Shirts | R3: =VLOOKUP(C3,'products '!$A$2:$H$3072,5,0) -> Roadster | S3: =VLOOKUP(C3,'products '!$A$2:$H$3072,6,0) -> 40 | T3: =VLOOKUP(C3,'products '!$A$2:$H$3072,7,0) -> Black | U3: =VLOOKUP(C3,'products '!$A$2:$H$3072,8,0) -> 4
A4: OD0003 | B4: C003 | C4: P0001 | D4: =RANDBETWEEN(DATE(2021,1,1),DATE(2023,3,31)) -> 44444 | E4: =TEXT(Table1[[#This Row],[Date]],"mmm") -> Sep | F4: =TEXT(Table1[[#This Row],[Date]],"yyyy") -> 2021 | G4: 351 | H4: 0.3 | I4: {=_xlfn.IFS(Table1[[#This Row],[Discount]]<=0.2,"Low",Table1[[#This Row],[Discount]]<=0.4,"Medium",Table1[[#This Row],[Discount]]>0.4,"High")} -> Medium | J4: =Table1[[#This Row],[Original Price]]*(1-Table1[[#This Row],[Discount]]) -> 245.7 | K4: =VLOOKUP(B4,customers!$A$2:$D$101,2,0) -> 36 | L4: {=_xlfn.IFS(Table1[[#This Row],[Age]]<=12,"Kids",Table1[[#This Row],[Age]]<=19,"Teenage",Table1[[#This Row],[Age]]<=29,"Young Adult",Table1[[#This Row],[Age]]<=45,"Adult",Table1[[#This Row],[Age]]>=46,"Senior")} -> Adult | M4: =VLOOKUP(B4,customers!A$2:D$101,3,0) -> Mumbai | N4: =VLOOKUP(B4,customers!$A$2:$D$101,4,0) -> Maharashtra | O4: =VLOOKUP(C4,'products '!$A$2:$H$3072,2,0) -> Women | P4: =VLOOKUP(C4,'products '!$A$2:$H$3072,3,0) -> Topwear | Q4: =VLOOKUP(C4,'products '!$A$2:$H$3072,4,0) -> T-Shirts | R4: =VLOOKUP(C4,'products '!$A$2:$H$3072,5,0) -> Roadster | S4: =VLOOKUP(C4,'products '!$A$2:$H$3072,6,0) -> 40 | T4: =VLOOKUP(C4,'products '!$A$2:$H$3072,7,0) -> Black | U4: =VLOOKUP(C4,'products '!$A$2:$H$3072,8,0) -> 4
A5: OD0004 | B5: C004 | C5: P0001 | D5: =RANDBETWEEN(DATE(2021,1,1),DATE(2023,3,31)) -> 45007 | E5: =TEXT(Table1[[#This Row],[Date]],"mmm") -> Mar | F5: =TEXT(Table1[[#This Row],[Date]],"yyyy") -> 2023 | G5: 352 | H5: 0.25 | I5: {=_xlfn.IFS(Table1[[#This Row],[Discount]]<=0.2,"Low",Table1[[#This Row],[Discount]]<=0.4,"Medium",Table1[[#This Row],[Discount]]>0.4,"High")} -> Medium | J5: =Table1[[#This Row],[Original Price]]*(1-Table1[[#This Row],[Discount]]) -> 264 | K5: =VLOOKUP(B5,customers!$A$2:$D$101,2,0) -> 40 | L5: {=_xlfn.IFS(Table1[[#This Row],[Age]]<=12,"Kids",Table1[[#This Row],[Age]]<=19,"Teenage",Table1[[#This Row],[Age]]<=29,"Young Adult",Table1[[#This Row],[Age]]<=45,"Adult",Table1[[#This Row],[Age]]>=46,"Senior")} -> Adult | M5: =VLOOKUP(B5,customers!A$2:D$101,3,0) -> Pune | N5: =VLOOKUP(B5,customers!$A$2:$D$101,4,0) -> Maharashtra | O5: =VLOOKUP(C5,'products '!$A$2:$H$3072,2,0) -> Women | P5: =VLOOKUP(C5,'products '!$A$2:$H$3072,3,0) -> Topwear | Q5: =VLOOKUP(C5,'products '!$A$2:$H$3072,4,0) -> T-Shirts | R5: =VLOOKUP(C5,'products '!$A$2:$H$3072,5,0) -> Roadster | S5: =VLOOKUP(C5,'products '!$A$2:$H$3072,6,0) -> 40 | T5: =VLOOKUP(C5,'products '!$A$2:$H$3072,7,0) -> Black | U5: =VLOOKUP(C5,'products '!$A$2:$H$3072,8,0) -> 4
A6: OD0005 | B6: C005 | C6: P0001 | D6: =RANDBETWEEN(DATE(2021,1,1),DATE(2023,3,31)) -> 44785 | E6: =TEXT(Table1[[#This Row],[Date]],"mmm") -> Aug | F6: =TEXT(Table1[[#This Row],[Date]],"yyyy") -> 2022 | G6: 353 | H6: 0.25 | I6: {=_xlfn.IFS(Table1[[#This Row],[Discount]]<=0.2,"Low",Table1[[#This Row],[Discount]]<=0.4,"Medium",Table1[[#This Row],[Discount]]>0.4,"High")} -> Medium | J6: =Table1[[#This Row],[Original Price]]*(1-Table1[[#This Row],[Discount]]) -> 264.75 | K6: =VLOOKUP(B6,customers!$A$2:$D$101,2,0) -> 25 | L6: {=_xlfn.IFS(Table1[[#This Row],[Age]]<=12,"Kids",Table1[[#This Row],[Age]]<=19,"Teenage",Table1[[#This Row],[Age]]<=29,"Young Adult",Table1[[#This Row],[Age]]<=45,"Adult",Table1[[#This Row],[Age]]>=46,"Senior")} -> Young Adult | M6: =VLOOKUP(B6,customers!A$2:D$101,3,0) -> Pune | N6: =VLOOKUP(B6,customers!$A$2:$D$101,4,0) -> Maharashtra | O6: =VLOOKUP(C6,'products '!$A$2:$H$3072,2,0) -> Women | P6: =VLOOKUP(C6,'products '!$A$2:$H$3072,3,0) -> Topwear | Q6: =VLOOKUP(C6,'products '!$A$2:$H$3072,4,0) -> T-Shirts | R6: =VLOOKUP(C6,'products '!$A$2:$H$3072,5,0) -> Roadster | S6: =VLOOKUP(C6,'products '!$A$2:$H$3072,6,0) -> 40 | T6: =VLOOKUP(C6,'products '!$A$2:$H$3072,7,0) -> Black | U6: =VLOOKUP(C6,'products '!$A$2:$H$3072,8,0) -> 4
A7: OD0006 | B7: C006 | C7: P0002 | D7: =RANDBETWEEN(DATE(2021,1,1),DATE(2023,3,31)) -> 44943 | E7: =TEXT(Table1[[#This Row],[Date]],"mmm") -> Jan | F7: =TEXT(Table1[[#This Row],[Date]],"yyyy") -> 2023 | G7: 354 | H7: 0.3 | I7: {=_xlfn.IFS(Table1[[#This Row],[Discount]]<=0.2,"Low",Table1[[#This Row],[Discount]]<=0.4,"Medium",Table1[[#This Row],[Discount]]>0.4,"High")} -> Medium | J7: =Table1[[#This Row],[Original Price]]*(1-Table1[[#This Row],[Discount]]) -> 247.8 | K7: =VLOOKUP(B7,customers!$A$2:$D$101,2,0) -> 16 | L7: {=_xlfn.IFS(Table1[[#This Row],[Age]]<=12,"Kids",Table1[[#This Row],[Age]]<=19,"Teenage",Table1[[#This Row],[Age]]<=29,"Young Adult",Table1[[#This Row],[Age]]<=45,"Adult",Table1[[#This Row],[Age]]>=46,"Senior")} -> Teenage | M7: =VLOOKUP(B7,customers!A$2:D$101,3,0) -> Pune | N7: =VLOOKUP(B7,customers!$A$2:$D$101,4,0) -> Maharashtra | O7: =VLOOKUP(C7,'products '!$A$2:$H$3072,2,0) -> Women | P7: =VLOOKUP(C7,'products '!$A$2:$H$3072,3,0) -> Topwear | Q7: =VLOOKUP(C7,'products '!$A$2:$H$3072,4,0) -> T-Shirts | R7: =VLOOKUP(C7,'products '!$A$2:$H$3072,5,0) -> Roadster | S7: =VLOOKUP(C7,'products '!$A$2:$H$3072,6,0) -> 40 | T7: =VLOOKUP(C7,'products '!$A$2:$H$3072,7,0) -> Blue | U7: =VLOOKUP(C7,'products '!$A$2:$H$3072,8,0) -> 5
A8: OD0007 | B8: C007 | C8: P0003 | D8: =RANDBETWEEN(DATE(2021,1,1),DATE(2023,3,31)) -> 44219 | E8: =TEXT(Table1[[#This Row],[Date]],"mmm") -> Jan | F8: =TEXT(Table1[[#This Row],[Date]],"yyyy") -> 2021 | G8: 355 | H8: 0.3 | I8: {=_xlfn.IFS(Table1[[#This Row],[Discount]]<=0.2,"Low",Table1[[#This Row],[Discount]]<=0.4,"Medium",Table1[[#This Row],[Discount]]>0.4,"High")} -> Medium | J8: =Table1[[#This Row],[Original Price]]*(1-Table1[[#This Row],[Discount]]) -> 248.5 | K8: =VLOOKUP(B8,customers!$A$2:$D$101,2,0) -> 23 | L8: {=_xlfn.IFS(Table1[[#This Row],[Age]]<=12,"Kids",Table1[[#This Row],[Age]]<=19,"Teenage",Table1[[#This Row],[Age]]<=29,"Young Adult",Table1[[#This Row],[Age]]<=45,"Adult",Table1[[#This Row],[Age]]>=46,"Senior")} -> Young Adult | M8: =VLOOKUP(B8,customers!A$2:D$101,3,0) -> Pune | N8: =VLOOKUP(B8,customers!$A$2:$D$101,4,0) -> Maharashtra | O8: =VLOOKUP(C8,'products '!$A$2:$H$3072,2,0) -> Women | P8: =VLOOKUP(C8,'products '!$A$2:$H$3072,3,0) -> Topwear | Q8: =VLOOKUP(C8,'products '!$A$2:$H$3072,4,0) -> T-Shirts | R8: =VLOOKUP(C8,'products '!$A$2:$H$3072,5,0) -> Roadster | S8: =VLOOKUP(C8,'products '!$A$2:$H$3072,6,0) -> 42 | T8: =VLOOKUP(C8,'products '!$A$2:$H$3072,7,0) -> White | U8: =VLOOKUP(C8,'products '!$A$2:$H$3072,8,0) -> 3
A9: OD0008 | B9: C008 | C9: P0004 | D9: =RANDBETWEEN(DATE(2021,1,1),DATE(2023,3,31)) -> 44253 | E9: =TEXT(Table1[[#This Row],[Date]],"mmm") -> Feb | F9: =TEXT(Table1[[#This Row],[Date]],"yyyy") -> 2021 | G9: 356 | H9: 0.3 | I9: {=_xlfn.IFS(Table1[[#This Row],[Discount]]<=0.2,"Low",Table1[[#This Row],[Discount]]<=0.4,"Medium",Table1[[#This Row],[Discount]]>0.4,"High")} -> Medium | J9: =Table1[[#This Row],[Original Price]]*(1-Table1[[#This Row],[Discount]]) -> 249.2 | K9: =VLOOKUP(B9,customers!$A$2:$D$101,2,0) -> 22 | L9: {=_xlfn.IFS(Table1[[#This Row],[Age]]<=12,"Kids",Table1[[#This Row],[Age]]<=19,"Teenage",Table1[[#This Row],[Age]]<=29,"Young Adult",Table1[[#This Row],[Age]]<=45,"Adult",Table1[[#This Row],[Age]]>=46,"Senior")} -> Young Adult | M9: =VLOOKUP(B9,customers!A$2:D$101,3,0) -> Pune | N9: =VLOOKUP(B9,customers!$A$2:$D$101,4,0) -> Maharashtra | O9: =VLOOKUP(C9,'products '!$A$2:$H$3072,2,0) -> Women | P9: =VLOOKUP(C9,'products '!$A$2:$H$3072,3,0) -> Topwear | Q9: =VLOOKUP(C9,'products '!$A$2:$H$3072,4,0) -> T-Shirts | R9: =VLOOKUP(C9,'products '!$A$2:$H$3072,5,0) -> Roadster | S9: =VLOOKUP(C9,'products '!$A$2:$H$3072,6,0) -> 44 | T9: =VLOOKUP(C9,'products '!$A$2:$H$3072,7,0) -> Green | U9: =VLOOKUP(C9,'products '!$A$2:$H$3072,8,0) -> 2
A10: OD0009 | B10: C009 | C10: P0005 | D10: =RANDBETWEEN(DATE(2021,1,1),DATE(2023,3,31)) -> 44529 | E10: =TEXT(Table1[[#This Row],[Date]],"mmm") -> Nov | F10: =TEXT(Table1[[#This Row],[Date]],"yyyy") -> 2021 | G10: 2222 | H10: 0.4 | I10: {=_xlfn.IFS(Table1[[#This Row],[Discount]]<=0.2,"Low",Table1[[#This Row],[Discount]]<=0.4,"Medium",Table1[[#This Row],[Discount]]>0.4,"High")} -> Medium | J10: =Table1[[#This Row],[Original Price]]*(1-Table1[[#This Row],[Discount]]) -> 1333.2 | K10: =VLOOKUP(B10,customers!$A$2:$D$101,2,0) -> 17 | L10: {=_xlfn.IFS(Table1[[#This Row],[Age]]<=12,"Kids",Table1[[#This Row],[Age]]<=19,"Teenage",Table1[[#This Row],[Age]]<=29,"Young Adult",Table1[[#This Row],[Age]]<=45,"Adult",Table1[[#This Row],[Age]]>=46,"Senior")} -> Teenage | M10: =VLOOKUP(B10,customers!A$2:D$101,3,0) -> Hyderabad | N10: =VLOOKUP(B10,customers!$A$2:$D$101,4,0) -> Telangana | O10: =VLOOKUP(C10,'products '!$A$2:$H$3072,2,0) -> Women | P10: =VLOOKUP(C10,'products '!$A$2:$H$3072,3,0) -> Topwear | Q10: =VLOOKUP(C10,'products '!$A$2:$H$3072,4,0) -> T-Shirts | R10: =VLOOKUP(C10,'products '!$A$2:$H$3072,5,0) -> Puma | S10: =VLOOKUP(C10,'products '!$A$2:$H$3072,6,0) -> 38 | T10: =VLOOKUP(C10,'products '!$A$2:$H$3072,7,0) -> Olive | U10: =VLOOKUP(C10,'products '!$A$2:$H$3072,8,0) -> 5
A11: OD0010 | B11: C010 | C11: P0006 | D11: =RANDBETWEEN(DATE(2021,1,1),DATE(2023,3,31)) -> 44778 | E11: =TEXT(Table1[[#This Row],[Date]],"mmm") -> Aug | F11: =TEXT(Table1[[#This Row],[Date]],"yyyy") -> 2022 | G11: 2342 | H11: 0.4 | I11: {=_xlfn.IFS(Table1[[#This Row],[Discount]]<=0.2,"Low",Table1[[#This Row],[Discount]]<=0.4,"Medium",Table1[[#This Row],[Discount]]>0.4,"High")} -> Medium | J11: =Table1[[#This Row],[Original Price]]*(1-Table1[[#This Row],[Discount]]) -> 1405.2 | K11: =VLOOKUP(B11,customers!$A$2:$D$101,2,0) -> 19 | L11: {=_xlfn.IFS(Table1[[#This Row],[Age]]<=12,"Kids",Table1[[#This Row],[Age]]<=19,"Teenage",Table1[[#This Row],[Age]]<=29,"Young Adult",Table1[[#This Row],[Age]]<=45,"Adult",Table1[[#This Row],[Age]]>=46,"Senior")} -> Teenage | M11: =VLOOKUP(B11,customers!A$2:D$101,3,0) -> Hyderabad | N11: =VLOOKUP(B11,customers!$A$2:$D$101,4,0) -> Telangana | O11: =VLOOKUP(C11,'products '!$A$2:$H$3072,2,0) -> Women | P11: =VLOOKUP(C11,'products '!$A$2:$H$3072,3,0) -> Topwear | Q11: =VLOOKUP(C11,'products '!$A$2:$H$3072,4,0) -> T-Shirts | R11: =VLOOKUP(C11,'products '!$A$2:$H$3072,5,0) -> Puma | S11: =VLOOKUP(C11,'products '!$A$2:$H$3072,6,0) -> 46 | T11: =VLOOKUP(C11,'products '!$A$2:$H$3072,7,0) -> Pink | U11: =VLOOKUP(C11,'products '!$A$2:$H$3072,8,0) -> 4
A12: OD0011 | B12: C011 | C12: P0007 | D12: =RANDBETWEEN(DATE(2021,1,1),DATE(2023,3,31)) -> 44290 | E12: =TEXT(Table1[[#This Row],[Date]],"mmm") -> Apr | F12: =TEXT(Table1[[#This Row],[Date]],"yyyy") -> 2021 | G12: 2241 | H12: 0.4 | I12: {=_xlfn.IFS(Table1[[#This Row],[Discount]]<=0.2,"Low",Table1[[#This Row],[Discount]]<=0.4,"Medium",Table1[[#This Row],[Discount]]>0.4,"High")} -> Medium | J12: =Table1[[#This Row],[Original Price]]*(1-Table1[[#This Row],[Discount]]) -> 1344.6 | K12: =VLOOKUP(B12,customers!$A$2:$D$101,2,0) -> 18 | L12: {=_xlfn.IFS(Table1[[#This Row],[Age]]<=12,"Kids",Table1[[#This Row],[Age]]<=19,"Teenage",Table1[[#This Row],[Age]]<=29,"Young Adult",Table1[[#This Row],[Age]]<=45,"Adult",Table1[[#This Row],[Age]]>=46,"Senior")} -> Teenage | M12: =VLOOKUP(B12,customers!A$2:D$101,3,0) -> Hyderabad | N12: =VLOOKUP(B12,customers!$A$2:$D$101,4,0) -> Telangana | O12: =VLOOKUP(C12,'products '!$A$2:$H$3072,2,0) -> Women | P12: =VLOOKUP(C12,'products '!$A$2:$H$3072,3,0) -> Topwear | Q12: =VLOOKUP(C12,'products '!$A$2:$H$3072,4,0) -> T-Shirts | R12: =VLOOKUP(C12,'products '!$A$2:$H$3072,5,0) -> Puma | S12: =VLOOKUP(C12,'products '!$A$2:$H$3072,6,0) -> 38 | T12: =VLOOKUP(C12,'products '!$A$2:$H$3072,7,0) -> Orange | U12: =VLOOKUP(C12,'products '!$A$2:$H$3072,8,0) -> 3
A13: OD0012 | B13: C012 | C13: P0007 | D13: =RANDBETWEEN(DATE(2021,1,1),DATE(2023,3,31)) -> 44992 | E13: =TEXT(Table1[[#This Row],[Date]],"mmm") -> Mar | F13: =TEXT(Table1[[#This Row],[Date]],"yyyy") -> 2023 | G13: 2253 | H13: 0.4 | I13: {=_xlfn.IFS(Table1[[#This Row],[Discount]]<=0.2,"Low",Table1[[#This Row],[Discount]]<=0.4,"Medium",Table1[[#This Row],[Discount]]>0.4,"High")} -> Medium | J13: =Table1[[#This Row],[Original Price]]*(1-Table1[[#This Row],[Discount]]) -> 1351.8 | K13: =VLOOKUP(B13,customers!$A$2:$D$101,2,0) -> 20 | L13: {=_xlfn.IFS(Table1[[#This Row],[Age]]<=12,"Kids",Table1[[#This Row],[Age]]<=19,"Teenage",Table1[[#This Row],[Age]]<=29,"Young Adult",Table1[[#This Row],[Age]]<=45,"Adult",Table1[[#This Row],[Age]]>=46,"Senior")} -> Young Adult | M13: =VLOOKUP(B13,customers!A$2:D$101,3,0) -> Hyderabad | N13: =VLOOKUP(B13,customers!$A$2:$D$101,4,0) -> Telangana | O13: =VLOOKUP(C13,'products '!$A$2:$H$3072,2,0) -> Women | P13: =VLOOKUP(C13,'products '!$A$2:$H$3072,3,0) -> Topwear | Q13: =VLOOKUP(C13,'products '!$A$2:$H$3072,4,0) -> T-Shirts | R13: =VLOOKUP(C13,'products '!$A$2:$H$3072,5,0) -> Puma | S13: =VLOOKUP(C13,'products '!$A$2:$H$3072,6,0) -> 38 | T13: =VLOOKUP(C13,'products '!$A$2:$H$3072,7,0) -> Orange | U13: =VLOOKUP(C13,'products '!$A$2:$H$3072,8,0) -> 3
... A3072: OD3071 | B3072: C056 | C3072: P2711 | D3072: =RANDBETWEEN(DATE(2021,1,1),DATE(2023,3,31)) -> 44209 | E3072: =TEXT(Table1[[#This Row],[Date]],"mmm") -> Jan | F3072: =TEXT(Table1[[#This Row],[Date]],"yyyy") -> 2021 | G3072: 555 | H3072: 0.25 | I3072: {=_xlfn.IFS(Table1[[#This Row],[Discount]]<=0.2,"Low",Table1[[#This Row],[Discount]]<=0.4,"Medium",Table1[[#This Row],[Discount]]>0.4,"High")} -> Medium | J3072: =Table1[[#This Row],[Original Price]]*(1-Table1[[#This Row],[Discount]]) -> 416.25 | K3072: =VLOOKUP(B3072,customers!$A$2:$D$101,2,0) -> 19 | L3072: {=_xlfn.IFS(Table1[[#This Row],[Age]]<=12,"Kids",Table1[[#This Row],[Age]]<=19,"Teenage",Table1[[#This Row],[Age]]<=29,"Young Adult",Table1[[#This Row],[Age]]<=45,"Adult",Table1[[#This Row],[Age]]>=46,"Senior")} -> Teenage | M3072: =VLOOKUP(B3072,customers!A$2:D$101,3,0) -> Sagar | N3072: =VLOOKUP(B3072,customers!$A$2:$D$101,4,0) -> Madhya Pradesh | O3072: =VLOOKUP(C3072,'products '!$A$2:$H$3072,2,0) -> Kids | P3072: =VLOOKUP(C3072,'products '!$A$2:$H$3072,3,0) -> Girls Clothing | Q3072: =VLOOKUP(C3072,'products '!$A$2:$H$3072,4,0) -> Shorts | R3072: =VLOOKUP(C3072,'products '!$A$2:$H$3072,5,0) -> Here&Now | S3072: =VLOOKUP(C3072,'products '!$A$2:$H$3072,6,0) -> 5-6Y | T3072: =VLOOKUP(C3072,'products '!$A$2:$H$3072,7,0) -> Sea Green | U3072: =VLOOKUP(C3072,'products '!$A$2:$H$3072,8,0) -> 4
A3073: OD3072 | B3073: C057 | C3073: P2712 | D3073: =RANDBETWEEN(DATE(2021,1,1),DATE(2023,3,31)) -> 44587 | E3073: =TEXT(Table1[[#This Row],[Date]],"mmm") -> Jan | F3073: =TEXT(Table1[[#This Row],[Date]],"yyyy") -> 2022 | G3073: =RANDBETWEEN(600, 2000) -> 1544 | H3073: 0.3 | I3073: {=_xlfn.IFS(Table1[[#This Row],[Discount]]<=0.2,"Low",Table1[[#This Row],[Discount]]<=0.4,"Medium",Table1[[#This Row],[Discount]]>0.4,"High")} -> Medium | J3073: =Table1[[#This Row],[Original Price]]*(1-Table1[[#This Row],[Discount]]) -> 1080.8 | K3073: =VLOOKUP(B3073,customers!$A$2:$D$101,2,0) -> 20 | L3073: {=_xlfn.IFS(Table1[[#This Row],[Age]]<=12,"Kids",Table1[[#This Row],[Age]]<=19,"Teenage",Table1[[#This Row],[Age]]<=29,"Young Adult",Table1[[#This Row],[Age]]<=45,"Adult",Table1[[#This Row],[Age]]>=46,"Senior")} -> Young Adult | M3073: =VLOOKUP(B3073,customers!A$2:D$101,3,0) -> Sagar | N3073: =VLOOKUP(B3073,customers!$A$2:$D$101,4,0) -> Madhya Pradesh | O3073: =VLOOKUP(C3073,'products '!$A$2:$H$3072,2,0) -> Kids | P3073: =VLOOKUP(C3073,'products '!$A$2:$H$3072,3,0) -> Girls Clothing | Q3073: =VLOOKUP(C3073,'products '!$A$2:$H$3072,4,0) -> Shorts | R3073: =VLOOKUP(C3073,'products '!$A$2:$H$3072,5,0) -> Here&Now | S3073: =VLOOKUP(C3073,'products '!$A$2:$H$3072,6,0) -> 5-6Y | T3073: =VLOOKUP(C3073,'products '!$A$2:$H$3072,7,0) -> Yellow | U3073: =VLOOKUP(C3073,'products '!$A$2:$H$3072,8,0) -> 4
A3074: OD3073 | B3074: C058 | C3074: P2713 | D3074: =RANDBETWEEN(DATE(2021,1,1),DATE(2023,3,31)) -> 44711 | E3074: =TEXT(Table1[[#This Row],[Date]],"mmm") -> May | F3074: =TEXT(Table1[[#This Row],[Date]],"yyyy") -> 2022 | G3074: =RANDBETWEEN(600, 2000) -> 753 | H3074: 0.3 | I3074: {=_xlfn.IFS(Table1[[#This Row],[Discount]]<=0.2,"Low",Table1[[#This Row],[Discount]]<=0.4,"Medium",Table1[[#This Row],[Discount]]>0.4,"High")} -> Medium | J3074: =Table1[[#This Row],[Original Price]]*(1-Table1[[#This Row],[Discount]]) -> 527.1 | K3074: =VLOOKUP(B3074,customers!$A$2:$D$101,2,0) -> 21 | L3074: {=_xlfn.IFS(Table1[[#This Row],[Age]]<=12,"Kids",Table1[[#This Row],[Age]]<=19,"Teenage",Table1[[#This Row],[Age]]<=29,"Young Adult",Table1[[#This Row],[Age]]<=45,"Adult",Table1[[#This Row],[Age]]>=46,"Senior")} -> Young Adult | M3074: =VLOOKUP(B3074,customers!A$2:D$101,3,0) -> Indore | N3074: =VLOOKUP(B3074,customers!$A$2:$D$101,4,0) -> Madhya Pradesh | O3074: =VLOOKUP(C3074,'products '!$A$2:$H$3072,2,0) -> Kids | P3074: =VLOOKUP(C3074,'products '!$A$2:$H$3072,3,0) -> Girls Clothing | Q3074: =VLOOKUP(C3074,'products '!$A$2:$H$3072,4,0) -> Shorts | R3074: =VLOOKUP(C3074,'products '!$A$2:$H$3072,5,0) -> Here&Now | S3074: =VLOOKUP(C3074,'products '!$A$2:$H$3072,6,0) -> 5-6Y | T3074: =VLOOKUP(C3074,'products '!$A$2:$H$3072,7,0) -> Blue | U3074: =VLOOKUP(C3074,'products '!$A$2:$H$3072,8,0) -> 3
A3075: OD3074 | B3075: C059 | C3075: P2714 | D3075: =RANDBETWEEN(DATE(2021,1,1),DATE(2023,3,31)) -> 44319 | E3075: =TEXT(Table1[[#This Row],[Date]],"mmm") -> May | F3075: =TEXT(Table1[[#This Row],[Date]],"yyyy") -> 2021 | G3075: =RANDBETWEEN(600, 2000) -> 1354 | H3075: 0.3 | I3075: {=_xlfn.IFS(Table1[[#This Row],[Discount]]<=0.2,"Low",Table1[[#This Row],[Discount]]<=0.4,"Medium",Table1[[#This Row],[Discount]]>0.4,"High")} -> Medium | J3075: =Table1[[#This Row],[Original Price]]*(1-Table1[[#This Row],[Discount]]) -> 947.8 | K3075: =VLOOKUP(B3075,customers!$A$2:$D$101,2,0) -> 22 | L3075: {=_xlfn.IFS(Table1[[#This Row],[Age]]<=12,"Kids",Table1[[#This Row],[Age]]<=19,"Teenage",Table1[[#This Row],[Age]]<=29,"Young Adult",Table1[[#This Row],[Age]]<=45,"Adult",Table1[[#This Row],[Age]]>=46,"Senior")} -> Young Adult | M3075: =VLOOKUP(B3075,customers!A$2:D$101,3,0) -> Indore | N3075: =VLOOKUP(B3075,customers!$A$2:$D$101,4,0) -> Madhya Pradesh | O3075: =VLOOKUP(C3075,'products '!$A$2:$H$3072,2,0) -> Kids | P3075: =VLOOKUP(C3075,'products '!$A$2:$H$3072,3,0) -> Girls Clothing | Q3075: =VLOOKUP(C3075,'products '!$A$2:$H$3072,4,0) -> Shorts | R3075: =VLOOKUP(C3075,'products '!$A$2:$H$3072,5,0) -> Here&Now | S3075: =VLOOKUP(C3075,'products '!$A$2:$H$3072,6,0) -> 5-6Y | T3075: =VLOOKUP(C3075,'products '!$A$2:$H$3072,7,0) -> White | U3075: =VLOOKUP(C3075,'products '!$A$2:$H$3072,8,0) -> 5
A3076: OD3075 | B3076: C060 | C3076: P2715 | D3076: =RANDBETWEEN(DATE(2021,1,1),DATE(2023,3,31)) -> 44565 | E3076: =TEXT(Table1[[#This Row],[Date]],"mmm") -> Jan | F3076: =TEXT(Table1[[#This Row],[Date]],"yyyy") -> 2022 | G3076: =RANDBETWEEN(600, 2000) -> 1989 | H3076: 0.25 | I3076: {=_xlfn.IFS(Table1[[#This Row],[Discount]]<=0.2,"Low",Table1[[#This Row],[Discount]]<=0.4,"Medium",Table1[[#This Row],[Discount]]>0.4,"High")} -> Medium | J3076: =Table1[[#This Row],[Original Price]]*(1-Table1[[#This Row],[Discount]]) -> 1491.75 | K3076: =VLOOKUP(B3076,customers!$A$2:$D$101,2,0) -> 16 | L3076: {=_xlfn.IFS(Table1[[#This Row],[Age]]<=12,"Kids",Table1[[#This Row],[Age]]<=19,"Teenage",Table1[[#This Row],[Age]]<=29,"Young Adult",Table1[[#This Row],[Age]]<=45,"Adult",Table1[[#This Row],[Age]]>=46,"Senior")} -> Teenage | M3076: =VLOOKUP(B3076,customers!A$2:D$101,3,0) -> Kanpur | N3076: =VLOOKUP(B3076,customers!$A$2:$D$101,4,0) -> Uttar Pradesh | O3076: =VLOOKUP(C3076,'products '!$A$2:$H$3072,2,0) -> Kids | P3076: =VLOOKUP(C3076,'products '!$A$2:$H$3072,3,0) -> Girls Clothing | Q3076: =VLOOKUP(C3076,'products '!$A$2:$H$3072,4,0) -> Shorts | R3076: =VLOOKUP(C3076,'products '!$A$2:$H$3072,5,0) -> Here&Now | S3076: =VLOOKUP(C3076,'products '!$A$2:$H$3072,6,0) -> 5-6Y | T3076: =VLOOKUP(C3076,'products '!$A$2:$H$3072,7,0) -> Green | U3076: =VLOOKUP(C3076,'products '!$A$2:$H$3072,8,0) -> 4
A3077: OD3076 | B3077: C061 | C3077: P2716 | D3077: =RANDBETWEEN(DATE(2021,1,1),DATE(2023,3,31)) -> 44785 | E3077: =TEXT(Table1[[#This Row],[Date]],"mmm") -> Aug | F3077: =TEXT(Table1[[#This Row],[Date]],"yyyy") -> 2022 | G3077: =RANDBETWEEN(600, 2000) -> 791 | H3077: 0.25 | I3077: {=_xlfn.IFS(Table1[[#This Row],[Discount]]<=0.2,"Low",Table1[[#This Row],[Discount]]<=0.4,"Medium",Table1[[#This Row],[Discount]]>0.4,"High")} -> Medium | J3077: =Table1[[#This Row],[Original Price]]*(1-Table1[[#This Row],[Discount]]) -> 593.25 | K3077: =VLOOKUP(B3077,customers!$A$2:$D$101,2,0) -> 17 | L3077: {=_xlfn.IFS(Table1[[#This Row],[Age]]<=12,"Kids",Table1[[#This Row],[Age]]<=19,"Teenage",Table1[[#This Row],[Age]]<=29,"Young Adult",Table1[[#This Row],[Age]]<=45,"Adult",Table1[[#This Row],[Age]]>=46,"Senior")} -> Teenage | M3077: =VLOOKUP(B3077,customers!A$2:D$101,3,0) -> Kanpur | N3077: =VLOOKUP(B3077,customers!$A$2:$D$101,4,0) -> Uttar Pradesh | O3077: =VLOOKUP(C3077,'products '!$A$2:$H$3072,2,0) -> Kids | P3077: =VLOOKUP(C3077,'products '!$A$2:$H$3072,3,0) -> Girls Clothing | Q3077: =VLOOKUP(C3077,'products '!$A$2:$H$3072,4,0) -> Shorts | R3077: =VLOOKUP(C3077,'products '!$A$2:$H$3072,5,0) -> Here&Now | S3077: =VLOOKUP(C3077,'products '!$A$2:$H$3072,6,0) -> 5-6Y | T3077: =VLOOKUP(C3077,'products '!$A$2:$H$3072,7,0) -> Olive | U3077: =VLOOKUP(C3077,'products '!$A$2:$H$3072,8,0) -> 2
A3078: OD3077 | B3078: C062 | C3078: P2717 | D3078: =RANDBETWEEN(DATE(2021,1,1),DATE(2023,3,31)) -> 44534 | E3078: =TEXT(Table1[[#This Row],[Date]],"mmm") -> Dec | F3078: =TEXT(Table1[[#This Row],[Date]],"yyyy") -> 2021 | G3078: =RANDBETWEEN(600, 2000) -> 1415 | H3078: 0.3 | I3078: {=_xlfn.IFS(Table1[[#This Row],[Discount]]<=0.2,"Low",Table1[[#This Row],[Discount]]<=0.4,"Medium",Table1[[#This Row],[Discount]]>0.4,"High")} -> Medium | J3078: =Table1[[#This Row],[Original Price]]*(1-Table1[[#This Row],[Discount]]) -> 990.5 | K3078: =VLOOKUP(B3078,customers!$A$2:$D$101,2,0) -> 18 | L3078: {=_xlfn.IFS(Table1[[#This Row],[Age]]<=12,"Kids",Table1[[#This Row],[Age]]<=19,"Teenage",Table1[[#This Row],[Age]]<=29,"Young Adult",Table1[[#This Row],[Age]]<=45,"Adult",Table1[[#This Row],[Age]]>=46,"Senior")} -> Teenage | M3078: =VLOOKUP(B3078,customers!A$2:D$101,3,0) -> Kanpur | N3078: =VLOOKUP(B3078,customers!$A$2:$D$101,4,0) -> Uttar Pradesh | O3078: =VLOOKUP(C3078,'products '!$A$2:$H$3072,2,0) -> Kids | P3078: =VLOOKUP(C3078,'products '!$A$2:$H$3072,3,0) -> Girls Clothing | Q3078: =VLOOKUP(C3078,'products '!$A$2:$H$3072,4,0) -> Shorts | R3078: =VLOOKUP(C3078,'products '!$A$2:$H$3072,5,0) -> HRX by Hrithik Roshan | S3078: =VLOOKUP(C3078,'products '!$A$2:$H$3072,6,0) -> 5-6Y | T3078: =VLOOKUP(C3078,'products '!$A$2:$H$3072,7,0) -> Pink | U3078: =VLOOKUP(C3078,'products '!$A$2:$H$3072,8,0) -> 5
A3079: OD3078 | B3079: C063 | C3079: P2718 | D3079: =RANDBETWEEN(DATE(2021,1,1),DATE(2023,3,31)) -> 44371 | E3079: =TEXT(Table1[[#This Row],[Date]],"mmm") -> Jun | F3079: =TEXT(Table1[[#This Row],[Date]],"yyyy") -> 2021 | G3079: =RANDBETWEEN(600, 2000) -> 953 | H3079: 0.3 | I3079: {=_xlfn.IFS(Table1[[#This Row],[Discount]]<=0.2,"Low",Table1[[#This Row],[Discount]]<=0.4,"Medium",Table1[[#This Row],[Discount]]>0.4,"High")} -> Medium | J3079: =Table1[[#This Row],[Original Price]]*(1-Table1[[#This Row],[Discount]]) -> 667.1 | K3079: =VLOOKUP(B3079,customers!$A$2:$D$101,2,0) -> 19 | L3079: {=_xlfn.IFS(Table1[[#This Row],[Age]]<=12,"Kids",Table1[[#This Row],[Age]]<=19,"Teenage",Table1[[#This Row],[Age]]<=29,"Young Adult",Table1[[#This Row],[Age]]<=45,"Adult",Table1[[#This Row],[Age]]>=46,"Senior")} -> Teenage | M3079: =VLOOKUP(B3079,customers!A$2:D$101,3,0) -> Kanpur | N3079: =VLOOKUP(B3079,customers!$A$2:$D$101,4,0) -> Uttar Pradesh | O3079: =VLOOKUP(C3079,'products '!$A$2:$H$3072,2,0) -> Kids | P3079: =VLOOKUP(C3079,'products '!$A$2:$H$3072,3,0) -> Girls Clothing | Q3079: =VLOOKUP(C3079,'products '!$A$2:$H$3072,4,0) -> Shorts | R3079: =VLOOKUP(C3079,'products '!$A$2:$H$3072,5,0) -> HRX by Hrithik Roshan | S3079: =VLOOKUP(C3079,'products '!$A$2:$H$3072,6,0) -> 5-6Y | T3079: =VLOOKUP(C3079,'products '!$A$2:$H$3072,7,0) -> Orange | U3079: =VLOOKUP(C3079,'products '!$A$2:$H$3072,8,0) -> 5
A3080: OD3079 | B3080: C064 | C3080: P2719 | D3080: =RANDBETWEEN(DATE(2021,1,1),DATE(2023,3,31)) -> 44924 | E3080: =TEXT(Table1[[#This Row],[Date]],"mmm") -> Dec | F3080: =TEXT(Table1[[#This Row],[Date]],"yyyy") -> 2022 | G3080: =RANDBETWEEN(600, 2000) -> 720 | H3080: 0.3 | I3080: {=_xlfn.IFS(Table1[[#This Row],[Discount]]<=0.2,"Low",Table1[[#This Row],[Discount]]<=0.4,"Medium",Table1[[#This Row],[Discount]]>0.4,"High")} -> Medium | J3080: =Table1[[#This Row],[Original Price]]*(1-Table1[[#This Row],[Discount]]) -> 504 | K3080: =VLOOKUP(B3080,customers!$A$2:$D$101,2,0) -> 20 | L3080: {=_xlfn.IFS(Table1[[#This Row],[Age]]<=12,"Kids",Table1[[#This Row],[Age]]<=19,"Teenage",Table1[[#This Row],[Age]]<=29,"Young Adult",Table1[[#This Row],[Age]]<=45,"Adult",Table1[[#This Row],[Age]]>=46,"Senior")} -> Young Adult | M3080: =VLOOKUP(B3080,customers!A$2:D$101,3,0) -> Aligarh | N3080: =VLOOKUP(B3080,customers!$A$2:$D$101,4,0) -> Uttar Pradesh | O3080: =VLOOKUP(C3080,'products '!$A$2:$H$3072,2,0) -> Kids | P3080: =VLOOKUP(C3080,'products '!$A$2:$H$3072,3,0) -> Girls Clothing | Q3080: =VLOOKUP(C3080,'products '!$A$2:$H$3072,4,0) -> Shorts | R3080: =VLOOKUP(C3080,'products '!$A$2:$H$3072,5,0) -> HRX by Hrithik Roshan | S3080: =VLOOKUP(C3080,'products '!$A$2:$H$3072,6,0) -> 5-6Y | T3080: =VLOOKUP(C3080,'products '!$A$2:$H$3072,7,0) -> Yellow | U3080: =VLOOKUP(C3080,'products '!$A$2:$H$3072,8,0) -> 5
A3081: OD3080 | B3081: C065 | C3081: P2720 | D3081: =RANDBETWEEN(DATE(2021,1,1),DATE(2023,3,31)) -> 44754 | E3081: =TEXT(Table1[[#This Row],[Date]],"mmm") -> Jul | F3081: =TEXT(Table1[[#This Row],[Date]],"yyyy") -> 2022 | G3081: =RANDBETWEEN(600, 2000) -> 1230 | H3081: 0.4 | I3081: {=_xlfn.IFS(Table1[[#This Row],[Discount]]<=0.2,"Low",Table1[[#This Row],[Discount]]<=0.4,"Medium",Table1[[#This Row],[Discount]]>0.4,"High")} -> Medium | J3081: =Table1[[#This Row],[Original Price]]*(1-Table1[[#This Row],[Discount]]) -> 738 | K3081: =VLOOKUP(B3081,customers!$A$2:$D$101,2,0) -> 21 | L3081: {=_xlfn.IFS(Table1[[#This Row],[Age]]<=12,"Kids",Table1[[#This Row],[Age]]<=19,"Teenage",Table1[[#This Row],[Age]]<=29,"Young Adult",Table1[[#This Row],[Age]]<=45,"Adult",Table1[[#This Row],[Age]]>=46,"Senior")} -> Young Adult | M3081: =VLOOKUP(B3081,customers!A$2:D$101,3,0) -> Aligarh | N3081: =VLOOKUP(B3081,customers!$A$2:$D$101,4,0) -> Uttar Pradesh | O3081: =VLOOKUP(C3081,'products '!$A$2:$H$3072,2,0) -> Kids | P3081: =VLOOKUP(C3081,'products '!$A$2:$H$3072,3,0) -> Girls Clothing | Q3081: =VLOOKUP(C3081,'products '!$A$2:$H$3072,4,0) -> Shorts | R3081: =VLOOKUP(C3081,'products '!$A$2:$H$3072,5,0) -> HRX by Hrithik Roshan | S3081: =VLOOKUP(C3081,'products '!$A$2:$H$3072,6,0) -> 5-6Y | T3081: =VLOOKUP(C3081,'products '!$A$2:$H$3072,7,0) -> Yellow | U3081: =VLOOKUP(C3081,'products '!$A$2:$H$3072,8,0) -> 4
A3082: OD3081 | B3082: C066 | C3082: P2721 | D3082: =RANDBETWEEN(DATE(2021,1,1),DATE(2023,3,31)) -> 44801 | E3082: =TEXT(Table1[[#This Row],[Date]],"mmm") -> Aug | F3082: =TEXT(Table1[[#This Row],[Date]],"yyyy") -> 2022 | G3082: =RANDBETWEEN(600, 2000) -> 624 | H3082: 0.4 | I3082: {=_xlfn.IFS(Table1[[#This Row],[Discount]]<=0.2,"Low",Table1[[#This Row],[Discount]]<=0.4,"Medium",Table1[[#This Row],[Discount]]>0.4,"High")} -> Medium | J3082: =Table1[[#This Row],[Original Price]]*(1-Table1[[#This Row],[Discount]]) -> 374.4 | K3082: =VLOOKUP(B3082,customers!$A$2:$D$101,2,0) -> 22 | L3082: {=_xlfn.IFS(Table1[[#This Row],[Age]]<=12,"Kids",Table1[[#This Row],[Age]]<=19,"Teenage",Table1[[#This Row],[Age]]<=29,"Young Adult",Table1[[#This Row],[Age]]<=45,"Adult",Table1[[#This Row],[Age]]>=46,"Senior")} -> Young Adult | M3082: =VLOOKUP(B3082,customers!A$2:D$101,3,0) -> Aligarh | N3082: =VLOOKUP(B3082,customers!$A$2:$D$101,4,0) -> Uttar Pradesh | O3082: =VLOOKUP(C3082,'products '!$A$2:$H$3072,2,0) -> Kids | P3082: =VLOOKUP(C3082,'products '!$A$2:$H$3072,3,0) -> Girls Clothing | Q3082: =VLOOKUP(C3082,'products '!$A$2:$H$3072,4,0) -> Shorts | R3082: =VLOOKUP(C3082,'products '!$A$2:$H$3072,5,0) -> HRX by Hrithik Roshan | S3082: =VLOOKUP(C3082,'products '!$A$2:$H$3072,6,0) -> 2-3Y | T3082: =VLOOKUP(C3082,'products '!$A$2:$H$3072,7,0) -> Yellow | U3082: =VLOOKUP(C3082,'products '!$A$2:$H$3072,8,0) -> 4
A3083: OD3082 | B3083: C067 | C3083: P2722 | D3083: =RANDBETWEEN(DATE(2021,1,1),DATE(2023,3,31)) -> 44994 | E3083: =TEXT(Table1[[#This Row],[Date]],"mmm") -> Mar | F3083: =TEXT(Table1[[#This Row],[Date]],"yyyy") -> 2023 | G3083: =RANDBETWEEN(600, 2000) -> 941 | H3083: 0.4 | I3083: {=_xlfn.IFS(Table1[[#This Row],[Discount]]<=0.2,"Low",Table1[[#This Row],[Discount]]<=0.4,"Medium",Table1[[#This Row],[Discount]]>0.4,"High")} -> Medium | J3083: =Table1[[#This Row],[Original Price]]*(1-Table1[[#This Row],[Discount]]) -> 564.6 | K3083: =VLOOKUP(B3083,customers!$A$2:$D$101,2,0) -> 23 | L3083: {=_xlfn.IFS(Table1[[#This Row],[Age]]<=12,"Kids",Table1[[#This Row],[Age]]<=19,"Teenage",Table1[[#This Row],[Age]]<=29,"Young Adult",Table1[[#This Row],[Age]]<=45,"Adult",Table1[[#This Row],[Age]]>=46,"Senior")} -> Young Adult | M3083: =VLOOKUP(B3083,customers!A$2:D$101,3,0) -> Aligarh | N3083: =VLOOKUP(B3083,customers!$A$2:$D$101,4,0) -> Uttar Pradesh | O3083: =VLOOKUP(C3083,'products '!$A$2:$H$3072,2,0) -> Kids | P3083: =VLOOKUP(C3083,'products '!$A$2:$H$3072,3,0) -> Girls Clothing | Q3083: =VLOOKUP(C3083,'products '!$A$2:$H$3072,4,0) -> Shorts | R3083: =VLOOKUP(C3083,'products '!$A$2:$H$3072,5,0) -> HRX by Hrithik Roshan | S3083: =VLOOKUP(C3083,'products '!$A$2:$H$3072,6,0) -> 2-3Y | T3083: =VLOOKUP(C3083,'products '!$A$2:$H$3072,7,0) -> Yellow | U3083: =VLOOKUP(C3083,'products '!$A$2:$H$3072,8,0) -> 4
A3084: OD3083 | B3084: C068 | C3084: P2723 | D3084: =RANDBETWEEN(DATE(2021,1,1),DATE(2023,3,31)) -> 44996 | E3084: =TEXT(Table1[[#This Row],[Date]],"mmm") -> Mar | F3084: =TEXT(Table1[[#This Row],[Date]],"yyyy") -> 2023 | G3084: =RANDBETWEEN(600, 2000) -> 1031 | H3084: 0.4 | I3084: {=_xlfn.IFS(Table1[[#This Row],[Discount]]<=0.2,"Low",Table1[[#This Row],[Discount]]<=0.4,"Medium",Table1[[#This Row],[Discount]]>0.4,"High")} -> Medium | J3084: =Table1[[#This Row],[Original Price]]*(1-Table1[[#This Row],[Discount]]) -> 618.6 | K3084: =VLOOKUP(B3084,customers!$A$2:$D$101,2,0) -> 18 | L3084: {=_xlfn.IFS(Table1[[#This Row],[Age]]<=12,"Kids",Table1[[#This Row],[Age]]<=19,"Teenage",Table1[[#This Row],[Age]]<=29,"Young Adult",Table1[[#This Row],[Age]]<=45,"Adult",Table1[[#This Row],[Age]]>=46,"Senior")} -> Teenage | M3084: =VLOOKUP(B3084,customers!A$2:D$101,3,0) -> Prayagraj | N3084: =VLOOKUP(B3084,customers!$A$2:$D$101,4,0) -> Uttar Pradesh | O3084: =VLOOKUP(C3084,'products '!$A$2:$H$3072,2,0) -> Kids | P3084: =VLOOKUP(C3084,'products '!$A$2:$H$3072,3,0) -> Girls Clothing | Q3084: =VLOOKUP(C3084,'products '!$A$2:$H$3072,4,0) -> Shorts | R3084: =VLOOKUP(C3084,'products '!$A$2:$H$3072,5,0) -> HRX by Hrithik Roshan | S3084: =VLOOKUP(C3084,'products '!$A$2:$H$3072,6,0) -> 2-3Y | T3084: =VLOOKUP(C3084,'products '!$A$2:$H$3072,7,0) -> Yellow | U3084: =VLOOKUP(C3084,'products '!$A$2:$H$3072,8,0) -> 5
... A3447: OD3446 | B3447: C031 | C3447: P3046 | D3447: =RANDBETWEEN(DATE(2021,1,1),DATE(2023,3,31)) -> 44460 | E3447: =TEXT(Table1[[#This Row],[Date]],"mmm") -> Sep | F3447: =TEXT(Table1[[#This Row],[Date]],"yyyy") -> 2021 | G3447: =RANDBETWEEN(600, 2000) -> 1229 | H3447: 0.39 | I3447: {=_xlfn.IFS(Table1[[#This Row],[Discount]]<=0.2,"Low",Table1[[#This Row],[Discount]]<=0.4,"Medium",Table1[[#This Row],[Discount]]>0.4,"High")} -> Medium | J3447: =Table1[[#This Row],[Original Price]]*(1-Table1[[#This Row],[Discount]]) -> 749.69 | K3447: =VLOOKUP(B3447,customers!$A$2:$D$101,2,0) -> 29 | L3447: {=_xlfn.IFS(Table1[[#This Row],[Age]]<=12,"Kids",Table1[[#This Row],[Age]]<=19,"Teenage",Table1[[#This Row],[Age]]<=29,"Young Adult",Table1[[#This Row],[Age]]<=45,"Adult",Table1[[#This Row],[Age]]>=46,"Senior")} -> Young Adult | M3447: =VLOOKUP(B3447,customers!A$2:D$101,3,0) -> Bengaluru | N3447: =VLOOKUP(B3447,customers!$A$2:$D$101,4,0) -> Karnataka | O3447: =VLOOKUP(C3447,'products '!$A$2:$H$3072,2,0) -> Kids | P3447: =VLOOKUP(C3447,'products '!$A$2:$H$3072,3,0) -> Footwear | Q3447: =VLOOKUP(C3447,'products '!$A$2:$H$3072,4,0) -> Sandals | R3447: =VLOOKUP(C3447,'products '!$A$2:$H$3072,5,0) -> MAX | S3447: =VLOOKUP(C3447,'products '!$A$2:$H$3072,6,0) -> 6-9M | T3447: =VLOOKUP(C3447,'products '!$A$2:$H$3072,7,0) -> Maroon | U3447: =VLOOKUP(C3447,'products '!$A$2:$H$3072,8,0) -> 3
A3448: OD3447 | B3448: C032 | C3448: P3047 | D3448: =RANDBETWEEN(DATE(2021,1,1),DATE(2023,3,31)) -> 44542 | E3448: =TEXT(Table1[[#This Row],[Date]],"mmm") -> Dec | F3448: =TEXT(Table1[[#This Row],[Date]],"yyyy") -> 2021 | G3448: 2245 | H3448: 0.39 | I3448: {=_xlfn.IFS(Table1[[#This Row],[Discount]]<=0.2,"Low",Table1[[#This Row],[Discount]]<=0.4,"Medium",Table1[[#This Row],[Discount]]>0.4,"High")} -> Medium | J3448: =Table1[[#This Row],[Original Price]]*(1-Table1[[#This Row],[Discount]]) -> 1369.45 | K3448: =VLOOKUP(B3448,customers!$A$2:$D$101,2,0) -> 41 | L3448: {=_xlfn.IFS(Table1[[#This Row],[Age]]<=12,"Kids",Table1[[#This Row],[Age]]<=19,"Teenage",Table1[[#This Row],[Age]]<=29,"Young Adult",Table1[[#This Row],[Age]]<=45,"Adult",Table1[[#This Row],[Age]]>=46,"Senior")} -> Adult | M3448: =VLOOKUP(B3448,customers!A$2:D$101,3,0) -> Bengaluru | N3448: =VLOOKUP(B3448,customers!$A$2:$D$101,4,0) -> Karnataka | O3448: =VLOOKUP(C3448,'products '!$A$2:$H$3072,2,0) -> Kids | P3448: =VLOOKUP(C3448,'products '!$A$2:$H$3072,3,0) -> Footwear | Q3448: =VLOOKUP(C3448,'products '!$A$2:$H$3072,4,0) -> Sandals | R3448: =VLOOKUP(C3448,'products '!$A$2:$H$3072,5,0) -> Puma | S3448: =VLOOKUP(C3448,'products '!$A$2:$H$3072,6,0) -> 6-9M | T3448: =VLOOKUP(C3448,'products '!$A$2:$H$3072,7,0) -> Maroon | U3448: =VLOOKUP(C3448,'products '!$A$2:$H$3072,8,0) -> 2
A3449: OD3448 | B3449: C033 | C3449: P3048 | D3449: =RANDBETWEEN(DATE(2021,1,1),DATE(2023,3,31)) -> 44377 | E3449: =TEXT(Table1[[#This Row],[Date]],"mmm") -> Jun | F3449: =TEXT(Table1[[#This Row],[Date]],"yyyy") -> 2021 | G3449: 2354 | H3449: 0.39 | I3449: {=_xlfn.IFS(Table1[[#This Row],[Discount]]<=0.2,"Low",Table1[[#This Row],[Discount]]<=0.4,"Medium",Table1[[#This Row],[Discount]]>0.4,"High")} -> Medium | J3449: =Table1[[#This Row],[Original Price]]*(1-Table1[[#This Row],[Discount]]) -> 1435.94 | K3449: =VLOOKUP(B3449,customers!$A$2:$D$101,2,0) -> 42 | L3449: {=_xlfn.IFS(Table1[[#This Row],[Age]]<=12,"Kids",Table1[[#This Row],[Age]]<=19,"Teenage",Table1[[#This Row],[Age]]<=29,"Young Adult",Table1[[#This Row],[Age]]<=45,"Adult",Table1[[#This Row],[Age]]>=46,"Senior")} -> Adult | M3449: =VLOOKUP(B3449,customers!A$2:D$101,3,0) -> Bengaluru | N3449: =VLOOKUP(B3449,customers!$A$2:$D$101,4,0) -> Karnataka | O3449: =VLOOKUP(C3449,'products '!$A$2:$H$3072,2,0) -> Kids | P3449: =VLOOKUP(C3449,'products '!$A$2:$H$3072,3,0) -> Footwear | Q3449: =VLOOKUP(C3449,'products '!$A$2:$H$3072,4,0) -> Sandals | R3449: =VLOOKUP(C3449,'products '!$A$2:$H$3072,5,0) -> Puma | S3449: =VLOOKUP(C3449,'products '!$A$2:$H$3072,6,0) -> 6-9M | T3449: =VLOOKUP(C3449,'products '!$A$2:$H$3072,7,0) -> Maroon | U3449: =VLOOKUP(C3449,'products '!$A$2:$H$3072,8,0) -> 5
A3450: OD3449 | B3450: C034 | C3450: P3049 | D3450: =RANDBETWEEN(DATE(2021,1,1),DATE(2023,3,31)) -> 44330 | E3450: =TEXT(Table1[[#This Row],[Date]],"mmm") -> May | F3450: =TEXT(Table1[[#This Row],[Date]],"yyyy") -> 2021 | G3450: 2214 | H3450: 0.39 | I3450: {=_xlfn.IFS(Table1[[#This Row],[Discount]]<=0.2,"Low",Table1[[#This Row],[Discount]]<=0.4,"Medium",Table1[[#This Row],[Discount]]>0.4,"High")} -> Medium | J3450: =Table1[[#This Row],[Original Price]]*(1-Table1[[#This Row],[Discount]]) -> 1350.54 | K3450: =VLOOKUP(B3450,customers!$A$2:$D$101,2,0) -> 43 | L3450: {=_xlfn.IFS(Table1[[#This Row],[Age]]<=12,"Kids",Table1[[#This Row],[Age]]<=19,"Teenage",Table1[[#This Row],[Age]]<=29,"Young Adult",Table1[[#This Row],[Age]]<=45,"Adult",Table1[[#This Row],[Age]]>=46,"Senior")} -> Adult | M3450: =VLOOKUP(B3450,customers!A$2:D$101,3,0) -> Bengaluru | N3450: =VLOOKUP(B3450,customers!$A$2:$D$101,4,0) -> Karnataka | O3450: =VLOOKUP(C3450,'products '!$A$2:$H$3072,2,0) -> Kids | P3450: =VLOOKUP(C3450,'products '!$A$2:$H$3072,3,0) -> Footwear | Q3450: =VLOOKUP(C3450,'products '!$A$2:$H$3072,4,0) -> Sandals | R3450: =VLOOKUP(C3450,'products '!$A$2:$H$3072,5,0) -> Puma | S3450: =VLOOKUP(C3450,'products '!$A$2:$H$3072,6,0) -> 6-9M | T3450: =VLOOKUP(C3450,'products '!$A$2:$H$3072,7,0) -> Grey | U3450: =VLOOKUP(C3450,'products '!$A$2:$H$3072,8,0) -> 4
A3451: OD3450 | B3451: C035 | C3451: P3050 | D3451: =RANDBETWEEN(DATE(2021,1,1),DATE(2023,3,31)) -> 44675 | E3451: =TEXT(Table1[[#This Row],[Date]],"mmm") -> Apr | F3451: =TEXT(Table1[[#This Row],[Date]],"yyyy") -> 2022 | G3451: 2365 | H3451: 0.3 | I3451: {=_xlfn.IFS(Table1[[#This Row],[Discount]]<=0.2,"Low",Table1[[#This Row],[Discount]]<=0.4,"Medium",Table1[[#This Row],[Discount]]>0.4,"High")} -> Medium | J3451: =Table1[[#This Row],[Original Price]]*(1-Table1[[#This Row],[Discount]]) -> 1655.5 | K3451: =VLOOKUP(B3451,customers!$A$2:$D$101,2,0) -> 44 | L3451: {=_xlfn.IFS(Table1[[#This Row],[Age]]<=12,"Kids",Table1[[#This Row],[Age]]<=19,"Teenage",Table1[[#This Row],[Age]]<=29,"Young Adult",Table1[[#This Row],[Age]]<=45,"Adult",Table1[[#This Row],[Age]]>=46,"Senior")} -> Adult | M3451: =VLOOKUP(B3451,customers!A$2:D$101,3,0) -> Bengaluru | N3451: =VLOOKUP(B3451,customers!$A$2:$D$101,4,0) -> Karnataka | O3451: =VLOOKUP(C3451,'products '!$A$2:$H$3072,2,0) -> Kids | P3451: =VLOOKUP(C3451,'products '!$A$2:$H$3072,3,0) -> Footwear | Q3451: =VLOOKUP(C3451,'products '!$A$2:$H$3072,4,0) -> Sandals | R3451: =VLOOKUP(C3451,'products '!$A$2:$H$3072,5,0) -> Puma | S3451: =VLOOKUP(C3451,'products '!$A$2:$H$3072,6,0) -> 6-9M | T3451: =VLOOKUP(C3451,'products '!$A$2:$H$3072,7,0) -> Grey | U3451: =VLOOKUP(C3451,'products '!$A$2:$H$3072,8,0) -> 2
A3452: OD3451 | B3452: C036 | C3452: P3051 | D3452: =RANDBETWEEN(DATE(2021,1,1),DATE(2023,3,31)) -> 44298 | E3452: =TEXT(Table1[[#This Row],[Date]],"mmm") -> Apr | F3452: =TEXT(Table1[[#This Row],[Date]],"yyyy") -> 2021 | G3452: 2541 | H3452: 0.3 | I3452: {=_xlfn.IFS(Table1[[#This Row],[Discount]]<=0.2,"Low",Table1[[#This Row],[Discount]]<=0.4,"Medium",Table1[[#This Row],[Discount]]>0.4,"High")} -> Medium | J3452: =Table1[[#This Row],[Original Price]]*(1-Table1[[#This Row],[Discount]]) -> 1778.7 | K3452: =VLOOKUP(B3452,customers!$A$2:$D$101,2,0) -> 45 | L3452: {=_xlfn.IFS(Table1[[#This Row],[Age]]<=12,"Kids",Table1[[#This Row],[Age]]<=19,"Teenage",Table1[[#This Row],[Age]]<=29,"Young Adult",Table1[[#This Row],[Age]]<=45,"Adult",Table1[[#This Row],[Age]]>=46,"Senior")} -> Adult | M3452: =VLOOKUP(B3452,customers!A$2:D$101,3,0) -> Bengaluru | N3452: =VLOOKUP(B3452,customers!$A$2:$D$101,4,0) -> Karnataka | O3452: =VLOOKUP(C3452,'products '!$A$2:$H$3072,2,0) -> Kids | P3452: =VLOOKUP(C3452,'products '!$A$2:$H$3072,3,0) -> Footwear | Q3452: =VLOOKUP(C3452,'products '!$A$2:$H$3072,4,0) -> Sandals | R3452: =VLOOKUP(C3452,'products '!$A$2:$H$3072,5,0) -> Puma | S3452: =VLOOKUP(C3452,'products '!$A$2:$H$3072,6,0) -> 6-9M | T3452: =VLOOKUP(C3452,'products '!$A$2:$H$3072,7,0) -> Grey | U3452: =VLOOKUP(C3452,'products '!$A$2:$H$3072,8,0) -> 5
A3453: OD3452 | B3453: C037 | C3453: P3052 | D3453: =RANDBETWEEN(DATE(2021,1,1),DATE(2023,3,31)) -> 44533 | E3453: =TEXT(Table1[[#This Row],[Date]],"mmm") -> Dec | F3453: =TEXT(Table1[[#This Row],[Date]],"yyyy") -> 2021 | G3453: 1235 | H3453: 0.3 | I3453: {=_xlfn.IFS(Table1[[#This Row],[Discount]]<=0.2,"Low",Table1[[#This Row],[Discount]]<=0.4,"Medium",Table1[[#This Row],[Discount]]>0.4,"High")} -> Medium | J3453: =Table1[[#This Row],[Original Price]]*(1-Table1[[#This Row],[Discount]]) -> 864.5 | K3453: =VLOOKUP(B3453,customers!$A$2:$D$101,2,0) -> 35 | L3453: {=_xlfn.IFS(Table1[[#This Row],[Age]]<=12,"Kids",Table1[[#This Row],[Age]]<=19,"Teenage",Table1[[#This Row],[Age]]<=29,"Young Adult",Table1[[#This Row],[Age]]<=45,"Adult",Table1[[#This Row],[Age]]>=46,"Senior")} -> Adult | M3453: =VLOOKUP(B3453,customers!A$2:D$101,3,0) -> Bengaluru | N3453: =VLOOKUP(B3453,customers!$A$2:$D$101,4,0) -> Karnataka | O3453: =VLOOKUP(C3453,'products '!$A$2:$H$3072,2,0) -> Kids | P3453: =VLOOKUP(C3453,'products '!$A$2:$H$3072,3,0) -> Footwear | Q3453: =VLOOKUP(C3453,'products '!$A$2:$H$3072,4,0) -> Sandals | R3453: =VLOOKUP(C3453,'products '!$A$2:$H$3072,5,0) -> Puma | S3453: =VLOOKUP(C3453,'products '!$A$2:$H$3072,6,0) -> 6-9M | T3453: =VLOOKUP(C3453,'products '!$A$2:$H$3072,7,0) -> Grey | U3453: =VLOOKUP(C3453,'products '!$A$2:$H$3072,8,0) -> 5
A3454: OD3453 | B3454: C038 | C3454: P3053 | D3454: =RANDBETWEEN(DATE(2021,1,1),DATE(2023,3,31)) -> 44389 | E3454: =TEXT(Table1[[#This Row],[Date]],"mmm") -> Jul | F3454: =TEXT(Table1[[#This Row],[Date]],"yyyy") -> 2021 | G3454: 22365 | H3454: 0.25 | I3454: {=_xlfn.IFS(Table1[[#This Row],[Discount]]<=0.2,"Low",Table1[[#This Row],[Discount]]<=0.4,"Medium",Table1[[#This Row],[Discount]]>0.4,"High")} -> Medium | J3454: =Table1[[#This Row],[Original Price]]*(1-Table1[[#This Row],[Discount]]) -> 16773.75 | K3454: =VLOOKUP(B3454,customers!$A$2:$D$101,2,0) -> 36 | L3454: {=_xlfn.IFS(Table1[[#This Row],[Age]]<=12,"Kids",Table1[[#This Row],[Age]]<=19,"Teenage",Table1[[#This Row],[Age]]<=29,"Young Adult",Table1[[#This Row],[Age]]<=45,"Adult",Table1[[#This Row],[Age]]>=46,"Senior")} -> Adult | M3454: =VLOOKUP(B3454,customers!A$2:D$101,3,0) -> Patna | N3454: =VLOOKUP(B3454,customers!$A$2:$D$101,4,0) -> Bihar | O3454: =VLOOKUP(C3454,'products '!$A$2:$H$3072,2,0) -> Kids | P3454: =VLOOKUP(C3454,'products '!$A$2:$H$3072,3,0) -> Footwear | Q3454: =VLOOKUP(C3454,'products '!$A$2:$H$3072,4,0) -> Sandals | R3454: =VLOOKUP(C3454,'products '!$A$2:$H$3072,5,0) -> Puma | S3454: =VLOOKUP(C3454,'products '!$A$2:$H$3072,6,0) -> 9-12M | T3454: =VLOOKUP(C3454,'products '!$A$2:$H$3072,7,0) -> Black | U3454: =VLOOKUP(C3454,'products '!$A$2:$H$3072,8,0) -> 4
A3455: OD3454 | B3455: C039 | C3455: P3054 | D3455: =RANDBETWEEN(DATE(2021,1,1),DATE(2023,3,31)) -> 44448 | E3455: =TEXT(Table1[[#This Row],[Date]],"mmm") -> Sep | F3455: =TEXT(Table1[[#This Row],[Date]],"yyyy") -> 2021 | G3455: 2245 | H3455: 0.25 | I3455: {=_xlfn.IFS(Table1[[#This Row],[Discount]]<=0.2,"Low",Table1[[#This Row],[Discount]]<=0.4,"Medium",Table1[[#This Row],[Discount]]>0.4,"High")} -> Medium | J3455: =Table1[[#This Row],[Original Price]]*(1-Table1[[#This Row],[Discount]]) -> 1683.75 | K3455: =VLOOKUP(B3455,customers!$A$2:$D$101,2,0) -> 37 | L3455: {=_xlfn.IFS(Table1[[#This Row],[Age]]<=12,"Kids",Table1[[#This Row],[Age]]<=19,"Teenage",Table1[[#This Row],[Age]]<=29,"Young Adult",Table1[[#This Row],[Age]]<=45,"Adult",Table1[[#This Row],[Age]]>=46,"Senior")} -> Adult | M3455: =VLOOKUP(B3455,customers!A$2:D$101,3,0) -> Patna | N3455: =VLOOKUP(B3455,customers!$A$2:$D$101,4,0) -> Bihar | O3455: =VLOOKUP(C3455,'products '!$A$2:$H$3072,2,0) -> Kids | P3455: =VLOOKUP(C3455,'products '!$A$2:$H$3072,3,0) -> Footwear | Q3455: =VLOOKUP(C3455,'products '!$A$2:$H$3072,4,0) -> Sandals | R3455: =VLOOKUP(C3455,'products '!$A$2:$H$3072,5,0) -> Puma | S3455: =VLOOKUP(C3455,'products '!$A$2:$H$3072,6,0) -> 9-12M | T3455: =VLOOKUP(C3455,'products '!$A$2:$H$3072,7,0) -> Yellow | U3455: =VLOOKUP(C3455,'products '!$A$2:$H$3072,8,0) -> 4
A3456: OD3455 | B3456: C040 | C3456: P3054 | D3456: =RANDBETWEEN(DATE(2021,1,1),DATE(2023,3,31)) -> 44361 | E3456: =TEXT(Table1[[#This Row],[Date]],"mmm") -> Jun | F3456: =TEXT(Table1[[#This Row],[Date]],"yyyy") -> 2021 | G3456: 2245 | H3456: 0.3 | I3456: {=_xlfn.IFS(Table1[[#This Row],[Discount]]<=0.2,"Low",Table1[[#This Row],[Discount]]<=0.4,"Medium",Table1[[#This Row],[Discount]]>0.4,"High")} -> Medium | J3456: =Table1[[#This Row],[Original Price]]*(1-Table1[[#This Row],[Discount]]) -> 1571.5 | K3456: =VLOOKUP(B3456,customers!$A$2:$D$101,2,0) -> 26 | L3456: {=_xlfn.IFS(Table1[[#This Row],[Age]]<=12,"Kids",Table1[[#This Row],[Age]]<=19,"Teenage",Table1[[#This Row],[Age]]<=29,"Young Adult",Table1[[#This Row],[Age]]<=45,"Adult",Table1[[#This Row],[Age]]>=46,"Senior")} -> Young Adult | M3456: =VLOOKUP(B3456,customers!A$2:D$101,3,0) -> Patna | N3456: =VLOOKUP(B3456,customers!$A$2:$D$101,4,0) -> Bihar | O3456: =VLOOKUP(C3456,'products '!$A$2:$H$3072,2,0) -> Kids | P3456: =VLOOKUP(C3456,'products '!$A$2:$H$3072,3,0) -> Footwear | Q3456: =VLOOKUP(C3456,'products '!$A$2:$H$3072,4,0) -> Sandals | R3456: =VLOOKUP(C3456,'products '!$A$2:$H$3072,5,0) -> Puma | S3456: =VLOOKUP(C3456,'products '!$A$2:$H$3072,6,0) -> 9-12M | T3456: =VLOOKUP(C3456,'products '!$A$2:$H$3072,7,0) -> Yellow | U3456: =VLOOKUP(C3456,'products '!$A$2:$H$3072,8,0) -> 4
A3457: OD3456 | B3457: C041 | C3457: P3054 | D3457: =RANDBETWEEN(DATE(2021,1,1),DATE(2023,3,31)) -> 44652 | E3457: =TEXT(Table1[[#This Row],[Date]],"mmm") -> Apr | F3457: =TEXT(Table1[[#This Row],[Date]],"yyyy") -> 2022 | G3457: 2542 | H3457: 0.3 | I3457: {=_xlfn.IFS(Table1[[#This Row],[Discount]]<=0.2,"Low",Table1[[#This Row],[Discount]]<=0.4,"Medium",Table1[[#This Row],[Discount]]>0.4,"High")} -> Medium | J3457: =Table1[[#This Row],[Original Price]]*(1-Table1[[#This Row],[Discount]]) -> 1779.4 | K3457: =VLOOKUP(B3457,customers!$A$2:$D$101,2,0) -> 27 | L3457: {=_xlfn.IFS(Table1[[#This Row],[Age]]<=12,"Kids",Table1[[#This Row],[Age]]<=19,"Teenage",Table1[[#This Row],[Age]]<=29,"Young Adult",Table1[[#This Row],[Age]]<=45,"Adult",Table1[[#This Row],[Age]]>=46,"Senior")} -> Young Adult | M3457: =VLOOKUP(B3457,customers!A$2:D$101,3,0) -> Patna | N3457: =VLOOKUP(B3457,customers!$A$2:$D$101,4,0) -> Bihar | O3457: =VLOOKUP(C3457,'products '!$A$2:$H$3072,2,0) -> Kids | P3457: =VLOOKUP(C3457,'products '!$A$2:$H$3072,3,0) -> Footwear | Q3457: =VLOOKUP(C3457,'products '!$A$2:$H$3072,4,0) -> Sandals | R3457: =VLOOKUP(C3457,'products '!$A$2:$H$3072,5,0) -> Puma | S3457: =VLOOKUP(C3457,'products '!$A$2:$H$3072,6,0) -> 9-12M | T3457: =VLOOKUP(C3457,'products '!$A$2:$H$3072,7,0) -> Yellow | U3457: =VLOOKUP(C3457,'products '!$A$2:$H$3072,8,0) -> 4
